// 代码生成时间: 2025-09-19 17:07:35
using Microsoft.VisualStudio.TestTools.UnitTesting;
using System;

/// <summary>
/// Summary description for AutomatedTestSuite
/// </summary>
[TestClass]
public class AutomatedTestSuite
{
    /// <summary>
    /// Initializes the test suite.
    /// </summary>
    [TestInitialize]
    public void InitializeTestSuite()
    {
        // Initialize any resources needed for the tests
    }

    /// <summary>
    /// Cleans up after the test suite.
    /// </summary>
    [TestCleanup]
    public void CleanupTestSuite()
    {
        // Clean up any resources used during the tests
    }

    /// <summary>
    /// Tests a successful scenario.
    /// </summary>
    [TestMethod]
    public void TestSuccessfulScenario()
    {
        try
        {
            // Arrange
            var expected = "Success";
            var actual = PerformOperation();

            // Act
            // Perform the operation that is being tested

            // Assert
            Assert.AreEqual(expected, actual, "The operation did not return the expected result.");
        }
        catch (Exception ex)
        {
            Assert.Fail("An unexpected exception occurred: " + ex.Message);
        }
    }

    /// <summary>
    /// Tests a failure scenario with error handling.
    /// </summary>
    [TestMethod]
    public void TestFailureScenarioWithErrorHandling()
    {
        try
        {
            // Arrange
            var expectedException = typeof(ArgumentException);
            var actualException = null;

            // Act
            try
            {
                // Perform the operation that is expected to throw an exception
                PerformOperationThatThrows();
            }
            catch (Exception ex)
            {
                actualException = ex;
            }

            // Assert
            Assert.IsNotNull(actualException, "An exception was expected but none was thrown.");
            Assert.IsInstanceOfType(actualException, expectedException, "The thrown exception was not of the expected type.");
        }
        catch (Exception ex)
        {
            Assert.Fail("An unexpected exception occurred: " + ex.Message);
        }
    }

    /// <summary>
    /// A sample method that performs an operation.
    /// </summary>
    /// <returns>The result of the operation.</returns>
    private string PerformOperation()
    {
        // The actual implementation of the operation being tested
        return "Success";
    }

    /// <summary>
    /// A sample method that performs an operation that is expected to throw an exception.
    /// </summary>
    private void PerformOperationThatThrows()
    {
        // The actual implementation of the operation that throws an exception
        throw new ArgumentException("Test exception");
    }
}
